Workbook

Sheet raw_monthly
A1: Month | B1: Consumption (kWh) | C1: Energy cost (€) | D1: Tax (€) | E1: Spot price avg (c/kWh) | F1: Temperature (°C) | G1: Total cost (spot, €) | H1: Fixed-price cost estimate (€)
A2: 45839 | B2: 737.06 | C2: 26.86 | D2: 6.85 | E2: 3.03 | F2: 19.2 | G2: 33.71 | H2: =B2*0.08 -> 58.9648
A3: 45870 | B3: 591.96 | C3: 43.81 | D3: 11.17 | E3: 6.93 | F3: 14.33 | G3: 54.98 | H3: =B3*0.08 -> 47.3568
A4: 45901 | B4: 593.11 | C4: 34.68 | D4: 8.85 | E4: 5.24 | F4: 13.19 | G4: 43.53 | H4: =B4*0.08 -> 47.4488
A5: 45931 | B5: 618.5 | C5: 38.16 | D5: 9.73 | E5: 6.24 | F5: 6.31 | G5: 47.89 | H5: =B5*0.08 -> 49.48
A6: 45962 | B6: 855.97 | C6: 48.25 | D6: 12.3 | E6: 6.02 | F6: 3.08 | G6: 60.55 | H6: =B6*0.08 -> 68.4776
A7: 45992 | B7: 1087.31 | C7: 47.72 | D7: 12.17 | E7: 4.51 | F7: 1.18 | G7: 59.89 | H7: =B7*0.08 -> 86.9848
A8: 46023 | B8: 1366.64 | C8: 176.12 | D8: 44.91 | E8: 14.72 | F8: -9.76 | G8: 221.03 | H8: =B8*0.08 -> 109.3312
A9: 46054 | B9: 1289.06 | C9: 189.31 | D9: 48.27 | E9: 17.22 | F9: -11.1 | G9: 237.58 | H9: =B9*0.08 -> 103.1248
A10: 46082 | B10: 967.66 | C10: 35.9 | D10: 9.15 | E10: 3.49 | F10: 2.82 | G10: 45.05 | H10: =B10*0.08 -> 77.4128
A11: 46113 | B11: 932.64 | C11: 55.33 | D11: 14.11 | E11: 6.21 | F11: 4.74 | G11: 69.44 | H11: =B11*0.08 -> 74.6112
A12: 46143 | B12: 859.32 | C12: 56.85 | D12: 14.5 | E12: 6.64 | F12: 11.29 | G12: 71.35 | H12: =B12*0.08 -> 68.7456
A13: 46174 | B13: 740.58 | C13: 42.87 | D13: 10.93 | E13: 5.69 | F13: 16.08 | G13: 53.8 | H13: =B13*0.08 -> 59.2464

Sheet raw_hourly
A1: Mittauspisteen tunnus | B1: Tuotteen tyyppi | C1: Resoluutio | D1: Yksikkötyyppi | E1: Lukeman tyyppi | F1: Consumption (kWh) | G1: Quality | H1: Timestamp_FI | I1: Timestamp_UTC | J1: Spot price hourly (c/kWh) | K1: Hour | L1: Month | M1: Price quartile
A2: 6.4300752e+17 | B2: 8716867000030 | C2: PT1H | D2: kWh | E2: BN01 | F2: 1.84 | G2: OK | H2: 45839 | I2: 2025-06-30T21:00:00Z | J2: 0.333 | K2: =HOUR(H2) -> 0 | L2: =TEXT(H2,"kk.vvvv") -> 07.2025 | M2: =IF(J2<=analysis!$A$84,"1. Cheapest",IF(J2<=analysis!$B$84,"2. Below average",IF(J2<=analysis!$C$84,"3. Above average","4. Most expensive"))) -> 1. Cheapest
A3: 6.4300752e+17 | B3: 8716867000030 | C3: PT1H | D3: kWh | E3: BN01 | F3: 0.31 | G3: OK | H3: 45839.042 | I3: 2025-06-30T22:00:00Z | J3: -0.003 | K3: =HOUR(H3) -> 1 | L3: =TEXT(H3,"kk.vvvv") -> 07.2025 | M3: =IF(J3<=analysis!$A$84,"1. Cheapest",IF(J3<=analysis!$B$84,"2. Below average",IF(J3<=analysis!$C$84,"3. Above average","4. Most expensive"))) -> 1. Cheapest
A4: 6.4300752e+17 | B4: 8716867000030 | C4: PT1H | D4: kWh | E4: BN01 | F4: 0.26 | G4: OK | H4: 45839.083 | I4: 2025-06-30T23:00:00Z | J4: -0.021 | K4: =HOUR(H4) -> 2 | L4: =TEXT(H4,"kk.vvvv") -> 07.2025 | M4: =IF(J4<=analysis!$A$84,"1. Cheapest",IF(J4<=analysis!$B$84,"2. Below average",IF(J4<=analysis!$C$84,"3. Above average","4. Most expensive"))) -> 1. Cheapest
A5: 6.4300752e+17 | B5: 8716867000030 | C5: PT1H | D5: kWh | E5: BN01 | F5: 0.3 | G5: OK | H5: 45839.125 | I5: 2025-07-01T00:00:00Z | J5: -0.021 | K5: =HOUR(H5) -> 3 | L5: =TEXT(H5,"kk.vvvv") -> 07.2025 | M5: =IF(J5<=analysis!$A$84,"1. Cheapest",IF(J5<=analysis!$B$84,"2. Below average",IF(J5<=analysis!$C$84,"3. Above average","4. Most expensive"))) -> 1. Cheapest
A6: 6.4300752e+17 | B6: 8716867000030 | C6: PT1H | D6: kWh | E6: BN01 | F6: 0.25 | G6: OK | H6: 45839.167 | I6: 2025-07-01T01:00:00Z | J6: -0.02 | K6: =HOUR(H6) -> 4 | L6: =TEXT(H6,"kk.vvvv") -> 07.2025 | M6: =IF(J6<=analysis!$A$84,"1. Cheapest",IF(J6<=analysis!$B$84,"2. Below average",IF(J6<=analysis!$C$84,"3. Above average","4. Most expensive"))) -> 1. Cheapest
A7: 6.4300752e+17 | B7: 8716867000030 | C7: PT1H | D7: kWh | E7: BN01 | F7: 0.45 | G7: OK | H7: 45839.208 | I7: 2025-07-01T02:00:00Z | J7: 0 | K7: =HOUR(H7) -> 5 | L7: =TEXT(H7,"kk.vvvv") -> 07.2025 | M7: =IF(J7<=analysis!$A$84,"1. Cheapest",IF(J7<=analysis!$B$84,"2. Below average",IF(J7<=analysis!$C$84,"3. Above average","4. Most expensive"))) -> 1. Cheapest
A8: 6.4300752e+17 | B8: 8716867000030 | C8: PT1H | D8: kWh | E8: BN01 | F8: 0.26 | G8: OK | H8: 45839.25 | I8: 2025-07-01T03:00:00Z | J8: 0.478 | K8: =HOUR(H8) -> 6 | L8: =TEXT(H8,"kk.vvvv") -> 07.2025 | M8: =IF(J8<=analysis!$A$84,"1. Cheapest",IF(J8<=analysis!$B$84,"2. Below average",IF(J8<=analysis!$C$84,"3. Above average","4. Most expensive"))) -> 1. Cheapest
A9: 6.4300752e+17 | B9: 8716867000030 | C9: PT1H | D9: kWh | E9: BN01 | F9: 0.26 | G9: OK | H9: 45839.292 | I9: 2025-07-01T04:00:00Z | J9: 1.03 | K9: =HOUR(H9) -> 7 | L9: =TEXT(H9,"kk.vvvv") -> 07.2025 | M9: =IF(J9<=analysis!$A$84,"1. Cheapest",IF(J9<=analysis!$B$84,"2. Below average",IF(J9<=analysis!$C$84,"3. Above average","4. Most expensive"))) -> 1. Cheapest
A10: 6.4300752e+17 | B10: 8716867000030 | C10: PT1H | D10: kWh | E10: BN01 | F10: 0.27 | G10: OK | H10: 45839.333 | I10: 2025-07-01T05:00:00Z | J10: 3.442 | K10: =HOUR(H10) -> 8 | L10: =TEXT(H10,"kk.vvvv") -> 07.2025 | M10: =IF(J10<=analysis!$A$84,"1. Cheapest",IF(J10<=analysis!$B$84,"2. Below average",IF(J10<=analysis!$C$84,"3. Above average","4. Most expensive"))) -> 2. Below average
A11: 6.4300752e+17 | B11: 8716867000030 | C11: PT1H | D11: kWh | E11: BN01 | F11: 1.49 | G11: OK | H11: 45839.375 | I11: 2025-07-01T06:00:00Z | J11: 2.392 | K11: =HOUR(H11) -> 9 | L11: =TEXT(H11,"kk.vvvv") -> 07.2025 | M11: =IF(J11<=analysis!$A$84,"1. Cheapest",IF(J11<=analysis!$B$84,"2. Below average",IF(J11<=analysis!$C$84,"3. Above average","4. Most expensive"))) -> 2. Below average
A12: 6.4300752e+17 | B12: 8716867000030 | C12: PT1H | D12: kWh | E12: BN01 | F12: 1.81 | G12: OK | H12: 45839.417 | I12: 2025-07-01T07:00:00Z | J12: 0.752 | K12: =HOUR(H12) -> 10 | L12: =TEXT(H12,"kk.vvvv") -> 07.2025 | M12: =IF(J12<=analysis!$A$84,"1. Cheapest",IF(J12<=analysis!$B$84,"2. Below average",IF(J12<=analysis!$C$84,"3. Above average","4. Most expensive"))) -> 1. Cheapest
A13: 6.4300752e+17 | B13: 8716867000030 | C13: PT1H | D13: kWh | E13: BN01 | F13: 0.23 | G13: OK | H13: 45839.458 | I13: 2025-07-01T08:00:00Z | J13: 0.817 | K13: =HOUR(H13) -> 11 | L13: =TEXT(H13,"kk.vvvv") -> 07.2025 | M13: =IF(J13<=analysis!$A$84,"1. Cheapest",IF(J13<=analysis!$B$84,"2. Below average",IF(J13<=analysis!$C$84,"3. Above average","4. Most expensive"))) -> 1. Cheapest
... A8761: 6.4300752e+17 | B8761: 8716867000030 | C8761: PT1H | D8761: kWh | E8761: BN01 | F8761: 0.79 | G8761: OK | H8761: 46203.958 | I8761: 2026-06-30T20:00:00Z | J8761: 4.55975 | K8761: =HOUR(H8761) -> 23 | L8761: =TEXT(H8761,"kk.vvvv") -> 06.2026 | M8761: =IF(J8761<=analysis!$A$84,"1. Cheapest",IF(J8761<=analysis!$B$84,"2. Below average",IF(J8761<=analysis!$C$84,"3. Above average","4. Most expensive"))) -> 2. Below average

Sheet analysis
A3: Hour | B3: Average consumption (kWh)
A4: 0 | B4: 0.87164384
A5: 1 | B5: 0.78219178
A6: 2 | B6: 0.73805479
A7: 3 | B7: 0.68575342
A8: 4 | B8: 0.76687671
A9: 5 | B9: 0.76956164
A10: 6 | B10: 0.93915068
A11: 7 | B11: 1.0873151
A12: 8 | B12: 1.1929315
A13: 9 | B13: 1.1962466
A14: 10 | B14: 1.0467397
A15: 11 | B15: 1.2067945
... A27: 23 | B27: 1.154
A28: Annual average per hour (kWh) | B28: 1.2145902
A32: Month | B32: Consumption (kWh)
A33: 07.2025 | B33: 737.06
A34: 08.2025 | B34: 591.96
A35: 09.2025 | B35: 593.11
A36: 10.2025 | B36: 618.5
A37: 11.2025 | B37: 855.97
A38: 12.2025 | B38: 1087.31
A39: 01.2026 | B39: 1366.64
A40: 02.2026 | B40: 1289.06
A41: 03.2026 | B41: 967.66
A42: 04.2026 | B42: 932.64
A43: 05.2026 | B43: 859.32
A44: 06.2026 | B44: 740.58
A45: Total consumption in kWh (year) | B45: 10639.81
A52: Month | B52: Peak load (kW) | L52: Peak hour of the year | M52: =VLOOKUP(LARGE(raw_hourly!$F$2:$F$8761,1),raw_hourly!$F$2:$H$8761,3,FALSE) -> 46066.292
A53: 01.2026 | B53: 5.68 | L53: Annual peak load (kW) | M53: 7.47
A54: 02.2026 | B54: 7.47
A55: 03.2026 | B55: 5.22
A56: 04.2026 | B56: 5.5
A57: 05.2026 | B57: 5.05
A58: 06.2026 | B58: 4.37
A59: 07.2025 | B59: 5.84
A60: 08.2025 | B60: 4.14
A61: 09.2025 | B61: 4.09
A62: 10.2025 | B62: 4.97
...

Sheet findings
B5: FINDINGS
B7: Overview
B8: This analysis covers one year from July 2025 to June 2026 hourly electricity consumption data from a Finnish household, combined with hourly spot price data and monthly billing data. Data was collected from Fingrid Datahub (hourly consumption), porssisahko.net (hourly spot prices) and Vaasan Sähkö (monthly billing summary). The data was validated by cross-checking hourly totals against monthly billing figures.
B10: Daily load profile
B11: Consumption follows a clear daily pattern, with a pronounced evening peak between 19:00–21:00 reaching around 2.4 kWh at 20:00, This is likely driven by cooking, showering and general household activity. Consumption is lowest between 02:00–04:00 at around 0.7 kWh.
B13: Seasonal variation
B14: Monthly consumption ranges from approximately 590 kWh in summer months to 1,370 kWh in January, coinciding with colder outdoor temperatures. This is supported by a clear inverse relationship between outdoor temperature and monthly consumption. The home is primarily heated with a heat-retaining fireplace, which stores and releases heat gradually, with air source heat pumps used for supplementary heating in winter and cooling in summer. Part of the electricity consumption increase in winter likely reflects heat pump use during the coldest periods, when the fireplace alone isn't sufficient.
B16: Peak load
B17: The highest single-hour consumption recorded during the year was 7.47 kW, occurring on 13 February 2026 at 07:00, likely related to heat pump use during cold weather combined with morning routines. Peak load figures like this are also relevant beyond this analysis, since many Finnish grid operators are moving toward capacity based grid tariffs, where a household's peak demand affects the network fee.
B19: Consumption vs. spot price
B20: Average hourly consumption increases steadily across price quartiles, from 0.997 kWh in the cheapest quartile to 1.534 kWh in the most expensive quartile with a 54% increase. This suggests consumption isn't shifted to avoid expensive hours, likely because heating demand and high market prices both peak during the same cold periods, rather than because of discretionary load.
B22: Cost comparison: spot price vs. fixed price
... B29: Spot prices used are Finland-wide market averages (Nord Pool via porssisahko.net), not the household's actual contracted rate. The fixed-price comparison uses a single estimated rate (8c/kWh) rather than an actual competing offer available at the time. One missing hour in the spot price dataset (29 March 2026, 03:00) due to Daylight saving time. It was filled in manually using the previous hour's value. DST transitions in the consumption data were approximated with a fixed offset (+3h summer, +2h winter) rather than exact transition timestamps. The effect on results is negligible.
